Exception on /cause_error [GET]
Traceback (most recent call last):
  File "D:\lab 9\env\Lib\site-packages\flask\app.py", line 1511, in wsgi_app
    response = self.full_dispatch_request()
               ^^^^^^^^^^^^^^^^^^^^^^^^^^^^
  File "D:\lab 9\env\Lib\site-packages\flask\app.py", line 919, in full_dispatch_request
    rv = self.handle_user_exception(e)
         ^^^^^^^^^^^^^^^^^^^^^^^^^^^^^
  File "D:\lab 9\env\Lib\site-packages\flask\app.py", line 917, in full_dispatch_request
    rv = self.dispatch_request()
         ^^^^^^^^^^^^^^^^^^^^^^^
  File "D:\lab 9\env\Lib\site-packages\flask\app.py", line 902, in dispatch_request
    return self.ensure_sync(self.view_functions[rule.endpoint])(**view_args)  # type: ignore[no-any-return]
           ^^^^^^^^^^^^^^^^^^^^^^^^^^^^^^^^^^^^^^^^^^^^^^^^^^^^^^^^^^^^^^^^^
  File "D:\lab 9\app.py", line 101, in cause_error
    1 / 0  # This will cause a 500 Internal Server Error
    ~~^~~
ZeroDivisionError: division by zero
Exception on / [GET]
Traceback (most recent call last):
  File "D:\lab 9\env\Lib\site-packages\sqlalchemy\engine\base.py", line 1964, in _exec_single_context
    self.dialect.do_execute(
  File "D:\lab 9\env\Lib\site-packages\sqlalchemy\engine\default.py", line 945, in do_execute
    cursor.execute(statement, parameters)
sqlite3.OperationalError: no such column: first_app.password

The above exception was the direct cause of the following exception:

Traceback (most recent call last):
  File "D:\lab 9\env\Lib\site-packages\flask\app.py", line 1511, in wsgi_app
    response = self.full_dispatch_request()
               ^^^^^^^^^^^^^^^^^^^^^^^^^^^^
  File "D:\lab 9\env\Lib\site-packages\flask\app.py", line 919, in full_dispatch_request
    rv = self.handle_user_exception(e)
         ^^^^^^^^^^^^^^^^^^^^^^^^^^^^^
  File "D:\lab 9\env\Lib\site-packages\flask\app.py", line 917, in full_dispatch_request
    rv = self.dispatch_request()
         ^^^^^^^^^^^^^^^^^^^^^^^
  File "D:\lab 9\env\Lib\site-packages\flask\app.py", line 902, in dispatch_request
    return self.ensure_sync(self.view_functions[rule.endpoint])(**view_args)  # type: ignore[no-any-return]
           ^^^^^^^^^^^^^^^^^^^^^^^^^^^^^^^^^^^^^^^^^^^^^^^^^^^^^^^^^^^^^^^^^
  File "D:\lab 9\app.py", line 58, in hello_world
    allpeople = db.session.execute(db.select(FirstApp)).scalars().all()
                ^^^^^^^^^^^^^^^^^^^^^^^^^^^^^^^^^^^^^^^
  File "D:\lab 9\env\Lib\site-packages\sqlalchemy\orm\scoping.py", line 779, in execute
    return self._proxied.execute(
           ^^^^^^^^^^^^^^^^^^^^^^
  File "D:\lab 9\env\Lib\site-packages\sqlalchemy\orm\session.py", line 2365, in execute
    return self._execute_internal(
           ^^^^^^^^^^^^^^^^^^^^^^^
  File "D:\lab 9\env\Lib\site-packages\sqlalchemy\orm\session.py", line 2251, in _execute_internal
    result: Result[Any] = compile_state_cls.orm_execute_statement(
                          ^^^^^^^^^^^^^^^^^^^^^^^^^^^^^^^^^^^^^^^^
  File "D:\lab 9\env\Lib\site-packages\sqlalchemy\orm\context.py", line 306, in orm_execute_statement
    result = conn.execute(
             ^^^^^^^^^^^^^
  File "D:\lab 9\env\Lib\site-packages\sqlalchemy\engine\base.py", line 1416, in execute
    return meth(
           ^^^^^
  File "D:\lab 9\env\Lib\site-packages\sqlalchemy\sql\elements.py", line 523, in _execute_on_connection
    return connection._execute_clauseelement(
           ^^^^^^^^^^^^^^^^^^^^^^^^^^^^^^^^^^
  File "D:\lab 9\env\Lib\site-packages\sqlalchemy\engine\base.py", line 1638, in _execute_clauseelement
    ret = self._execute_context(
          ^^^^^^^^^^^^^^^^^^^^^^
  File "D:\lab 9\env\Lib\site-packages\sqlalchemy\engine\base.py", line 1843, in _execute_context
    return self._exec_single_context(
           ^^^^^^^^^^^^^^^^^^^^^^^^^^
  File "D:\lab 9\env\Lib\site-packages\sqlalchemy\engine\base.py", line 1983, in _exec_single_context
    self._handle_dbapi_exception(
  File "D:\lab 9\env\Lib\site-packages\sqlalchemy\engine\base.py", line 2352, in _handle_dbapi_exception
    raise sqlalchemy_exception.with_traceback(exc_info[2]) from e
  File "D:\lab 9\env\Lib\site-packages\sqlalchemy\engine\base.py", line 1964, in _exec_single_context
    self.dialect.do_execute(
  File "D:\lab 9\env\Lib\site-packages\sqlalchemy\engine\default.py", line 945, in do_execute
    cursor.execute(statement, parameters)
sqlalchemy.exc.OperationalError: (sqlite3.OperationalError) no such column: first_app.password
[SQL: SELECT first_app.sno, first_app.fname, first_app.lname, first_app.email, first_app.password 
FROM first_app]
(Background on this error at: https://sqlalche.me/e/20/e3q8)
Exception on / [GET]
Traceback (most recent call last):
  File "D:\lab 9\env\Lib\site-packages\sqlalchemy\engine\base.py", line 1964, in _exec_single_context
    self.dialect.do_execute(
  File "D:\lab 9\env\Lib\site-packages\sqlalchemy\engine\default.py", line 945, in do_execute
    cursor.execute(statement, parameters)
sqlite3.OperationalError: no such column: first_app.password

The above exception was the direct cause of the following exception:

Traceback (most recent call last):
  File "D:\lab 9\env\Lib\site-packages\flask\app.py", line 1511, in wsgi_app
    response = self.full_dispatch_request()
               ^^^^^^^^^^^^^^^^^^^^^^^^^^^^
  File "D:\lab 9\env\Lib\site-packages\flask\app.py", line 919, in full_dispatch_request
    rv = self.handle_user_exception(e)
         ^^^^^^^^^^^^^^^^^^^^^^^^^^^^^
  File "D:\lab 9\env\Lib\site-packages\flask\app.py", line 917, in full_dispatch_request
    rv = self.dispatch_request()
         ^^^^^^^^^^^^^^^^^^^^^^^
  File "D:\lab 9\env\Lib\site-packages\flask\app.py", line 902, in dispatch_request
    return self.ensure_sync(self.view_functions[rule.endpoint])(**view_args)  # type: ignore[no-any-return]
           ^^^^^^^^^^^^^^^^^^^^^^^^^^^^^^^^^^^^^^^^^^^^^^^^^^^^^^^^^^^^^^^^^
  File "D:\lab 9\app.py", line 58, in hello_world
    allpeople = db.session.execute(db.select(FirstApp)).scalars().all()
                ^^^^^^^^^^^^^^^^^^^^^^^^^^^^^^^^^^^^^^^
  File "D:\lab 9\env\Lib\site-packages\sqlalchemy\orm\scoping.py", line 779, in execute
    return self._proxied.execute(
           ^^^^^^^^^^^^^^^^^^^^^^
  File "D:\lab 9\env\Lib\site-packages\sqlalchemy\orm\session.py", line 2365, in execute
    return self._execute_internal(
           ^^^^^^^^^^^^^^^^^^^^^^^
  File "D:\lab 9\env\Lib\site-packages\sqlalchemy\orm\session.py", line 2251, in _execute_internal
    result: Result[Any] = compile_state_cls.orm_execute_statement(
                          ^^^^^^^^^^^^^^^^^^^^^^^^^^^^^^^^^^^^^^^^
  File "D:\lab 9\env\Lib\site-packages\sqlalchemy\orm\context.py", line 306, in orm_execute_statement
    result = conn.execute(
             ^^^^^^^^^^^^^
  File "D:\lab 9\env\Lib\site-packages\sqlalchemy\engine\base.py", line 1416, in execute
    return meth(
           ^^^^^
  File "D:\lab 9\env\Lib\site-packages\sqlalchemy\sql\elements.py", line 523, in _execute_on_connection
    return connection._execute_clauseelement(
           ^^^^^^^^^^^^^^^^^^^^^^^^^^^^^^^^^^
  File "D:\lab 9\env\Lib\site-packages\sqlalchemy\engine\base.py", line 1638, in _execute_clauseelement
    ret = self._execute_context(
          ^^^^^^^^^^^^^^^^^^^^^^
  File "D:\lab 9\env\Lib\site-packages\sqlalchemy\engine\base.py", line 1843, in _execute_context
    return self._exec_single_context(
           ^^^^^^^^^^^^^^^^^^^^^^^^^^
  File "D:\lab 9\env\Lib\site-packages\sqlalchemy\engine\base.py", line 1983, in _exec_single_context
    self._handle_dbapi_exception(
  File "D:\lab 9\env\Lib\site-packages\sqlalchemy\engine\base.py", line 2352, in _handle_dbapi_exception
    raise sqlalchemy_exception.with_traceback(exc_info[2]) from e
  File "D:\lab 9\env\Lib\site-packages\sqlalchemy\engine\base.py", line 1964, in _exec_single_context
    self.dialect.do_execute(
  File "D:\lab 9\env\Lib\site-packages\sqlalchemy\engine\default.py", line 945, in do_execute
    cursor.execute(statement, parameters)
sqlalchemy.exc.OperationalError: (sqlite3.OperationalError) no such column: first_app.password
[SQL: SELECT first_app.sno, first_app.fname, first_app.lname, first_app.email, first_app.password 
FROM first_app]
(Background on this error at: https://sqlalche.me/e/20/e3q8)
